Workbook

Sheet Dashboard
B2: NetSage AI — Diagnosis Dashboard
B3: Auto-calculated from Cases, AI_vs_Human, and Rule_Checker — recalculates when those sheets change
B5: 30 | D5: =COUNTIF(AI_vs_Human!$B$2:$B$31,"Complete") -> 22 | F5: =COUNTIF(AI_vs_Human!$B$2:$B$31,"Pending") -> 8 | H5: =COUNTIF(AI_vs_Human!$H$2:$H$31,"yes")/COUNTIF(AI_vs_Human!$B$2:$B$31,"Complete") -> 0.77272727
B6: Total Cases | D6: Evidence Complete | F6: Evidence Pending | H6: AI Agreement Rate
B9: Cases by Issue Type (concept_tag)
B10: Issue Type | C10: Count
B11: ACL misconfiguration | C11: =COUNTIF(AI_vs_Human!$C$2:$C$31,B11) -> 1
B12: Access/trunk mode mismatch | C12: =COUNTIF(AI_vs_Human!$C$2:$C$31,B12) -> 1
B13: Application service disabled | C13: =COUNTIF(AI_vs_Human!$C$2:$C$31,B13) -> 1
B14: DHCP | C14: =COUNTIF(AI_vs_Human!$C$2:$C$31,B14) -> 1
B15: DHCP relay missing | C15: =COUNTIF(AI_vs_Human!$C$2:$C$31,B15) -> 1
B16: DHCP service disabled | C16: =COUNTIF(AI_vs_Human!$C$2:$C$31,B16) -> 1
B17: DNS | C17: =COUNTIF(AI_vs_Human!$C$2:$C$31,B17) -> 2
B18: Duplicate IP | C18: =COUNTIF(AI_vs_Human!$C$2:$C$31,B18) -> 1
B19: EtherChannel member mismatch | C19: =COUNTIF(AI_vs_Human!$C$2:$C$31,B19) -> 1
B20: FTP | C20: =COUNTIF(AI_vs_Human!$C$2:$C$31,B20) -> 1
B21: Gateway | C21: =COUNTIF(AI_vs_Human!$C$2:$C$31,B21) -> 1
B22: Gateway mismatch | C22: =COUNTIF(AI_vs_Human!$C$2:$C$31,B22) -> 1
B23: Inter-VLAN Routing | C23: =COUNTIF(AI_vs_Human!$C$2:$C$31,B23) -> 1 | N23: Complete | O23: =D5 -> 22
B24: Interface down | C24: =COUNTIF(AI_vs_Human!$C$2:$C$31,B24) -> 1 | N24: Pending | O24: =F5 -> 8
B25: Missing route | C25: =COUNTIF(AI_vs_Human!$C$2:$C$31,B25) -> 2
B26: NAT | C26: =COUNTIF(AI_vs_Human!$C$2:$C$31,B26) -> 1
B27: NAT misconfiguration | C27: =COUNTIF(AI_vs_Human!$C$2:$C$31,B27) -> 1
B28: Native VLAN mismatch | C28: =COUNTIF(AI_vs_Human!$C$2:$C$31,B28) -> 1
B29: Port security violation | C29: =COUNTIF(AI_vs_Human!$C$2:$C$31,B29) -> 1
B30: Routing protocol mismatch | C30: =COUNTIF(AI_vs_Human!$C$2:$C$31,B30) -> 2
B31: STP root bridge / port role | C31: =COUNTIF(AI_vs_Human!$C$2:$C$31,B31) -> 1
B32: Trunk allowed-VLAN list | C32: =COUNTIF(AI_vs_Human!$C$2:$C$31,B32) -> 1
B33: VLAN | C33: =COUNTIF(AI_vs_Human!$C$2:$C$31,B33) -> 1
B34: VLAN misconfiguration | C34: =COUNTIF(AI_vs_Human!$C$2:$C$31,B34) -> 2
B35: Wrong DNS server | C35: =COUNTIF(AI_vs_Human!$C$2:$C$31,B35) -> 1
B36: Wrong subnet mask | C36: =COUNTIF(AI_vs_Human!$C$2:$C$31,B36) -> 1
B39: Cases by Severity
B40: Severity | C40: Count
B41: High | C41: =COUNTIF(AI_vs_Human!$D$2:$D$31,B41) -> 13
B42: Medium | C42: =COUNTIF(AI_vs_Human!$D$2:$D$31,B42) -> 9
B43: Low | C43: =COUNTIF(AI_vs_Human!$D$2:$D$31,B43) -> 0
B44: Unknown | C44: =COUNTIF(AI_vs_Human!$D$2:$D$31,B44) -> 8
B47: Human Review Outcomes (evidence-complete cases only)
B48: Status | C48: Count
...

Sheet Cases
A1: case_id | B1: pkt_file | C1: evidence_file | D1: evidence_status | E1: symptom | F1: topology_note | G1: show_output | H1: expected_fault | I1: osi_layer | J1: concept_tag | K1: severity
A2: C01 | B2: Cisco__1__DNS_Problem_.pkt | D2: Pending | E2: PENDING — evidence not yet supplied for this DNS Problem case. | J2: DNS | K2: Unknown
A3: C02 | B3: Cisco__2__DHCP_Problem_.pkt | C3: Cisco @6.docx | D3: Complete | E3: PC3 was switched to DHCP mode and displayed 'DHCP request failed' — no IPv4 address, gateway, or DNS server was received. | F3: One Cisco 2911 router, one switch, and four PCs on a single LAN 192.168.10.0/24. Router provides DHCP via pool 'LAN' (network 192.168.10.0/24, default-router 192.168.10.1, dns-server 8.8.8.8, excluded 192.168.10.1). | G3: Router# show ip interface brief GigabitEthernet0/0 192.168.10.1 YES manual up up Router# show run | include dhcp no service dhcp ip dhcp pool LAN network 192.168.10.0 255.255.255.0 default-router 192.168.10.1 dns-server 8.8.8.8 | H3: DHCP service disabled on the router ('no service dhcp') despite the DHCP pool being fully configured | I3: Layer 7 (Application) | J3: DHCP service disabled | K3: High
A4: C03 | B4: Cisco__3__Gateway_Problem_.pkt | D4: Pending | E4: PENDING — evidence not yet supplied for this Gateway Problem case. | J4: Gateway | K4: Unknown
A5: C04 | B5: Cisco__4__ACL_.pkt | C5: Cisco @4.pdf | D5: Complete | E5: PC0 (192.168.10.10) could not reach Server0 (192.168.20.20) — ping showed 'Destination host unreachable' from the local gateway 192.168.10.1, 4 sent / 0 received / 100% loss. | F5: Router0 (G0/0 192.168.10.1/24 to Switch0/PC0, G0/1 192.168.20.1/24 to Switch1/PC1 and Server0), single router-on-a-stick style topology with two subnets. | G5: Router#show access-lists Extended IP access list 100 10 deny ip host 192.168.10.10 host 192.168.20.20 20 permit ip any any Router#show run interface gigabitEthernet 0/1 ip access-group 100 out | H5: Extended ACL 100 explicitly denies traffic from PC0 (192.168.10.10) to Server0 (192.168.20.20), applied outbound on Gi0/1 | I5: Layer 3/4 (Network/Transport) | J5: ACL misconfiguration | K5: High
A6: C05 | B6: Cisco__5__TRUNK_.pkt | C6: Cisco @15.pdf | D6: Complete | E6: Team needed to verify the inter-switch trunk carries both VLAN 10 (USERS) and VLAN 20 (STUDENTS); found only VLAN 1 and VLAN 20 permitted on Switch0 Fa0/2's allowed-VLAN list. | F6: Two Cisco 2960-24TT switches connected via Switch0 Fa0/2 <-> Switch1 Fa0/24. PC0/PC1 on Switch0, PC2/PC3 on Switch1. VLAN10=USERS, VLAN20=STUDENTS. | G6: Switch0#show interfaces trunk Fa0/2 802.1Q trunking Native VLAN 1 Vlans allowed on trunk: 1,20 Switch0#show vlan brief VLAN10 USERS active Fa0/1 VLAN20 STUDENTS active PC0>ping 192.168.20.12 -> 4/4 replies, 0% loss | H6: VLAN 10 not included in the trunk's allowed-VLAN list on Switch0 Fa0/2 (only VLAN 1 and 20 permitted) | I6: Layer 2 (Data Link) | J6: Trunk allowed-VLAN list | K6: Medium
A7: C06 | B7: Cisco__6__IP_Address_Conflict_.pkt | C7: Cisco @17.pdf | D7: Complete | E7: PC0 and PC1 were both assigned IPv4 address 192.168.10.10, producing an IP address conflict on the LAN. | F7: One Cisco 2960 switch with PC0 (Fa0/1), PC1 (Fa0/2), PC2 (Fa0/3) directly connected; subnet 192.168.10.0/24. | G7: PC0 IP config: 192.168.10.10/24, gateway 192.168.10.1 PC1 IP config (fault): 192.168.10.10/24 (duplicate of PC0) PC2>arp -a and ping 192.168.10.10 used to confirm which host responds | H7: Duplicate IP address 192.168.10.10 assigned to both PC0 and PC1 | I7: Layer 3 (Network) | J7: Duplicate IP | K7: Medium
A8: C07 | B8: Cisco__7__Default_Wrong_Gateway_.pkt | C8: Cisco @18.pdf | D8: Complete | E8: PC0 could ping its local gateway 192.168.10.1 but could not reach PC1 on 192.168.20.0/24 — ping to 192.168.20.10 returned 100% packet loss. | F8: Router0 (G0/0 192.168.10.1/24, G0/1 192.168.20.1/24), two switches, PC0 (192.168.10.10) and PC1 (192.168.20.10). | G8: PC0>ping 192.168.20.10 -> Request timed out (100% loss) PC0>ping 192.168.10.1 -> Reply received PC0 IP config shows default gateway is NOT 192.168.10.1 | H8: PC0 configured with an incorrect default gateway instead of the correct 192.168.10.1 | I8: Layer 3 (Network) | J8: Gateway mismatch | K8: High
A9: C08 | B9: Cisco__8__RIP_Routing_Error_.pkt | C9: Cisco @20.pdf | D9: Complete | E9: PC0 could no longer reach PC1 on the remote LAN after previously working; the RIP-learned route to 192.168.20.0/24 was missing from Router0's routing table. | F9: Router0 (G0/0 192.168.10.1/24, G0/1 10.0.12.1/30) and Router1 (G0/1 10.0.12.2/30, G0/0 192.168.20.1/24) run RIPv2, no auto-summary. PC0 on 192.168.10.0/24, PC1 on 192.168.20.0/24. | G9: Router1#show ip protocols Routing for Networks: 10.0.0.0 (192.168.20.0 statement missing) Router0#show ip route (no R-coded route for 192.168.20.0/24) | H9: Missing 'network 192.168.20.0' statement under Router1's RIP configuration | I9: Layer 3 (Network) | J9: Routing protocol mismatch | K9: High
A10: C09 | B10: Cisco__9__Post_Security_.pkt | C10: Cisco @22.pdf | D10: Complete | E10: PC0 lost connectivity to PC1; the switch port Fa0/1 entered an err-disabled state after a port-security violation. | F10: Cisco 2960 switch with PC0 (192.168.10.10, Fa0/1) and PC1 (192.168.10.11); Port Security enabled on Fa0/1 with one allowed secure MAC and violation mode = shutdown. | G10: Switch0#show port-security interface fa0/1 Port Security: Enabled Port Status: Secure-shutdown Security Violation Count: 1 %PSECURE-2: Security violation on Fa0/1 | H10: Incorrect secure MAC address configured on Fa0/1; PC0's real MAC triggered a security violation and err-disabled the port | I10: Layer 2 (Data Link) | J10: Port security violation | K10: High
A11: C10 | B11: Cisco__10__Wrong_Switch_Port_.pkt | C11: Cisco @23.pdf | D11: Complete | E11: PC0, expected in VLAN 10 (USERS) on Fa0/1, was not correctly reaching intended VLAN 10 peers because Fa0/1 was assigned to the wrong access VLAN. | F11: Cisco 2960-24TT (Switch0) with VLAN 10 (USERS) and VLAN 20 (STUDENTS). PC0 on Fa0/1 (should be VLAN10, 192.168.10.10/24), PC1 on Fa0/2 (VLAN20, 192.168.20.10/24). | G11: Switch0#show interfaces fastEthernet 0/1 switchport Administrative Mode: static access Access Mode VLAN: 20 (should be 10) | H11: Fa0/1 assigned to the wrong access VLAN (20 instead of 10) | I11: Layer 2 (Data Link) | J11: VLAN misconfiguration | K11: High
A12: C11 | B12: Cisco__11__Native_VLAN_Mismatch_.pkt | C12: Cisco @24.pdf | D12: Complete | E12: End-to-end connectivity between the two switches' PCs failed due to inconsistent native VLANs on the inter-switch trunk. | F12: Switch0 and Switch1 interconnected via Fa0/24; VLAN10 used for the PCs, VLAN20 used for the native-VLAN fault demonstration. | G12: Switch0#show interfaces trunk Fa0/24 802.1Q trunking Native VLAN: 10 Switch1#show interfaces trunk Fa0/24 802.1Q trunking Native VLAN: 20 | H12: Native VLAN mismatch across the Fa0/24 trunk (Switch0=VLAN10, Switch1=VLAN20) | I12: Layer 2 (Data Link) | J12: Native VLAN mismatch | K12: Medium
A13: C12 | B13: Cisco__12__STP_Problem_.pkt | C13: Cisco @27.pdf | D13: Complete | E13: Needed to confirm SW1 is the STP Root Bridge and that the redundant path in the SW1-SW2-SW3 triangle is correctly blocked to prevent a Layer-2 loop. | F13: SW1, SW2, SW3 form a Layer-2 triangle (PVST, VLAN 1); PC0 on SW2, PC1 on SW3. | G13: SW1#show spanning-tree vlan 1 Root ID Priority 4097 (This bridge is the root) SW3#show spanning-tree Fa0/2 Root FWD | Fa0/1 Alternate BLK | Fa0/10 Designated FWD | H13: SW1 not originally configured with the lowest STP priority to become Root Bridge (fixed by setting VLAN 1 priority to 4096 on SW1) | I13: Layer 2 (Data Link) | J13: STP root bridge / port role | K13: Medium
A14: C13 | B14: Cisco__13__DNS_Configuration_Error_.pkt | C14: Cisco @28.pdf | D14: Complete | E14: PC0 could ping Server0 by IP (192.168.10.11) but nslookup and ping to www.netsage.local both failed, indicating hostname resolution was not working. | F14: Single LAN 192.168.10.0/24: PC0 (client, 192.168.10.10) and Server0 (DNS+Web, 192.168.10.11) via Switch0. A record: www.netsage.local -> 192.168.10.11. | G14: PC0>nslookup www.netsage.local -> Request timed out (PC0's DNS server setting was wrong) After correcting PC0's DNS server to 192.168.10.11: nslookup www.netsage.local -> 192.168.10.11 (success) | H14: PC0 had an incorrect/missing DNS server configuration (should point to Server0 at 192.168.10.11) | I14: Layer 7 (Application) | J14: Wrong DNS server | K14: Medium
A15: C14 | B15: Cisco__14__NAT_Overload_Error_.pkt | C15: Cisco @9.docx | D15: Complete | E15: PC0 (192.168.10.10) could not reach the external server 198.51.100.10 — ping showed 4 sent / 0 received / 100% loss — even though the local gateway and Router0-to-Router1 path both worked. | F15: Router0 performs PAT/NAT overload for 192.168.10.0/24 (G0/0 inside 192.168.10.1, G0/1 outside 203.0.113.1). Router1 simulates the ISP. External Server0 at 198.51.100.10. | G15: Router0#show ip nat translations (empty) Router0#show running-config | include ip nat (overload rule missing — no 'ip nat inside source list 1 interface g0/1 overload') | H15: Missing NAT overload/PAT rule on Router0 ('ip nat inside source list 1 interface gigabitEthernet 0/1 overload' was removed) | I15: Layer 3 (Network) | J15: NAT misconfiguration | K15: High
A16: C15 | B16: Cisco__15__FTP_Server_Error_.pkt | D16: Pending | E16: PENDING — evidence not yet supplied for this FTP Server Error case. | J16: FTP | K16: Unknown
A17: C16 | B17: Cisco__16__Baseline_VLAN20_.pkt | D17: Pending | E17: PENDING — evidence not yet supplied for this Baseline VLAN20 case. | J17: VLAN | K17: Unknown
A18: C17 | B18: Cisco__17__DHCP_Problem_.pkt | D18: Pending | E18: PENDING — evidence not yet supplied for this (second) DHCP Problem case. | J18: DHCP | K18: Unknown
A19: C18 | B19: Cisco__18__DNS_Troubleshooting_.pkt | D19: Pending | E19: PENDING — evidence not yet supplied for this DNS Troubleshooting case. | J19: DNS | K19: Unknown
A20: C19 | B20: Cisco__19__Static_RouterError_.pkt | C20: Cisco @11.docx | D20: Complete | E20: PC0 could no longer reach PC1 at 192.168.30.10 — ping returned 100% packet loss — after previously working. | F20: Three-router chain: R0 (192.168.10.1 LAN, 10.0.0.1 to R1), R1 (10.0.0.2, 20.0.0.1 to R2), R2 (20.0.0.2, 192.168.30.1 LAN). | G20: R0#show ip route 192.168.10.0/24 and 10.0.0.0/30 connected; 20.0.0.0/30 via R1; NO route to 192.168.30.0/24 | H20: Static route to 192.168.30.0/24 via 10.0.0.2 was removed from Router0 ('no ip route 192.168.30.0 255.255.255.0 10.0.0.2') | I20: Layer 3 (Network) | J20: Missing route | K20: High
A21: C20 | B21: Cisco__20__Routing_Troubleshooting_.pkt | C21: Cisco @10.docx | D21: Complete | E21: PC0 could reach its own gateway but could not reach remote PC2 on 192.168.20.0/24. | F21: Two LANs (192.168.10.0/24, 192.168.20.0/24) connected via Router0 and Router1 across a 10.0.0.0/30 transit link. | G21: Router0#show ip route connected routes for 192.168.10.0/24 and 10.0.0.0/30 present; NO route for 192.168.20.0/24 | H21: Missing static routes on Router0 (to 192.168.20.0/24) and Router1 (return route to 192.168.10.0/24) | I21: Layer 3 (Network) | J21: Missing route | K21: High
A22: C21 | B22: Cisco__21__Wrong_SubnetMask_.pkt | C22: Cisco @12.docx | D22: Complete | E22: PC1 could not communicate correctly with PC0/PC2 on the same LAN due to an incorrect subnet mask. | F22: One router, one switch, three PCs, all intended for 192.168.10.0/24: PC0 (.10), PC1 (.11), PC2 (.12). | G22: PC1>ipconfig IPv4 Address: 192.168.10.11 Subnet Mask: 255.255.0.0 (should be 255.255.255.0) Default Gateway: 192.168.10.1 | H22: PC1 configured with subnet mask 255.255.0.0 instead of 255.255.255.0 | I22: Layer 3 (Network) | J22: Wrong subnet mask | K22: Medium
A23: C22 | B23: Cisco__22__OSPF_RoutingError_.pkt | C23: Cisco @13.docx | D23: Complete | E23: Router1 stopped learning Router0's LAN network via OSPF even though the R0-R1 OSPF adjacency remained FULL. | F23: Router0 (G0/0 192.168.10.1/24) and Router1 (G0/0 192.168.20.1/24) connected via 10.0.0.0/30, OSPF area 0. | G23: Router0#show run | section router ospf network 192.168.100.0 0.0.0.255 area 0 (wrong; actual LAN is 192.168.10.0/24) Router1#show ip route (no OSPF route to 192.168.10.0/24) | H23: Incorrect OSPF network statement on Router0 (192.168.100.0/24 instead of the actual LAN 192.168.10.0/24) | I23: Layer 3 (Network) | J23: Routing protocol mismatch | K23: High
A24: C23 | B24: Cisco__23__VLAN_Mismatch_.pkt | C24: Cisco @16.docx | D24: Complete | E24: PC0 could no longer ping PC1 after previously working — ping returned 4 sent / 4 lost, 100% packet loss. | F24: Single Cisco 2960-24TT switch; PC0 (Fa0/1) and PC1 (Fa0/2), both on 192.168.20.0/24, intended for VLAN 20. | G24: Switch0#show vlan brief Fa0/1 -> VLAN 20 Fa0/2 -> VLAN 30 (should be VLAN 20) | H24: Fa0/2 assigned to VLAN 30 instead of VLAN 20 | I24: Layer 2 (Data Link) | J24: VLAN misconfiguration | K24: High
A25: C24 | B25: Cisco__24__Shutdown_Interfaces_.pkt | C25: Cisco @14.docx | D25: Complete | E25: PC0 could not reach the router gateway 192.168.10.1 after the router's LAN interface was disabled. | F25: Router0 (2911) -> Switch0 (2960-24TT) -> PC0 (192.168.10.10/24); GigabitEthernet0/0 = 192.168.10.1/24. | G25: R0#show ip interface brief GigabitEthernet0/0 192.168.10.1 YES manual administratively down down | H25: GigabitEthernet0/0 administratively shut down on Router0 | I25: Layer 1 (Physical) | J25: Interface down | K25: High
A26: C25 | B26: Cisco__25__Access_Port_Error_.pkt | C26: Cisco @19.docx | D26: Complete | E26: PC1 could not reach PC2 on the same intended VLAN because the PC-facing switch port was operating as a trunk instead of an access port. | F26: SW1 and SW2 with a Gi0/1 inter-switch trunk (VLANs 10,20); PC1 (VLAN10, 192.168.10.10) and PC2 (VLAN10, 192.168.10.20) on SW2's Fa0/1/Fa0/2. | G26: SW2#show interfaces trunk Fa0/1 and Gi0/1 both show trunking (Fa0/1 should be an access port, not trunk) | H26: PC-facing interface Fa0/1 on SW2 configured as a trunk instead of an access port in VLAN 10 | I26: Layer 2 (Data Link) | J26: Access/trunk mode mismatch | K26: Medium
A27: C26 | B27: Cisco__26__EtherChannel_Error_.pkt | C27: Cisco @21.docx | D27: Complete | E27: The SW1-SW2 EtherChannel lost one of its three bundled physical links; show etherchannel summary showed Fa0/23 suspended (S) instead of bundled (P). | F27: Three FastEthernet links (Fa0/21-23) between SW1 and SW2 bundled into Port-Channel 1 using LACP. | G27: SW2#show etherchannel summary Po1(SU) Fa0/21(P) Fa0/22(P) Fa0/23(S) | H27: SW2 Fa0/23 configured with switchport mode access instead of trunk, and LACP passive instead of active, excluding it from the bundle | I27: Layer 2 (Data Link) | J27: EtherChannel member mismatch | K27: Medium
A28: C27 | B28: Cisco__27__HTTP_WebServer_Error_.pkt | C28: Cisco @26.docx | D28: Complete | E28: PC1 could ping Server1 successfully (0% loss) but the browser could not load http://192.168.20.10 — showed 'Server Reset Connection'. | F28: PC1 (192.168.10.10) -> Switch1 -> R1 (G0/0 192.168.10.1, G0/1 192.168.20.1) -> Switch2 -> Server1 (192.168.20.10). | G28: PC1>ping 192.168.20.10 -> 4/4 replies, 0% loss Browser: http://192.168.20.10 -> 'Server Reset Connection' Server1 Services -> HTTP: OFF | H28: HTTP service disabled on Server1 — an application-layer fault, not a network/IP issue | I28: Layer 7 (Application) | J28: Application service disabled | K28: Medium
A29: C28 | B29: Cisco__28__DHCP_Relay_Error_.pkt | C29: Cisco @25.docx | D29: Complete | E29: PC0 (VLAN 20) and PC1 (VLAN 30) both remained on DHCP but received no IPv4 address, subnet mask, or default gateway. | F29: Server0 (DHCP, 192.168.10.10) -> Switch0 -> Router0 (inter-VLAN routing, G0/1.20 and G0/1.30 subinterfaces) -> Switch1 -> PC0 (VLAN20)/PC1 (VLAN30). | G29: Router0#show run interface gigabitEthernet 0/1.20 (no ip helper-address configured) Router0#show run interface gigabitEthernet 0/1.30 (no ip helper-address configured) | H29: 'ip helper-address 192.168.10.10' removed from both G0/1.20 and G0/1.30 subinterfaces | I29: Layer 3 (Network) | J29: DHCP relay missing | K29: High
A30: C29 | B30: Cisco__29__NAT_Working_Baseline_.pkt | D30: Pending | E30: PENDING — evidence not yet supplied for this NAT Working Baseline case. | J30: NAT | K30: Unknown
A31: C30 | B31: Cisco__30__Inter-VLAN_Routing_.pkt | D31: Pending | E31: PENDING — evidence not yet supplied for this Inter-VLAN Routing case. | J31: Inter-VLAN Routing | K31: Unknown

Sheet AI_vs_Human
A1: case_id | B1: evidence_status | C1: concept_tag | D1: severity | E1: expected_fault | F1: ai_root_cause | G1: ai_confidence | H1: ai_matches_expected | I1: review_status | J1: reviewer_notes
A2: C01 | B2: Pending | C2: DNS | D2: Unknown | F2: Not yet diagnosed — evidence pending | H2: pending | I2: Pending Evidence | J2: Case not yet reviewed — awaiting evidence document.
A3: C02 | B3: Complete | C3: DHCP service disabled | D3: High | E3: DHCP service disabled on the router ('no service dhcp') despite the DHCP pool being fully configured | F3: DHCP service disabled on the router (no service dhcp) with the pool otherwise intact | G3: high | H3: yes | I3: Accepted | J3: AI diagnosis matched the expected fault and cited the correct evidence.
A4: C03 | B4: Pending | C4: Gateway | D4: Unknown | F4: Not yet diagnosed — evidence pending | H4: pending | I4: Pending Evidence | J4: Case not yet reviewed — awaiting evidence document.
A5: C04 | B5: Complete | C5: ACL misconfiguration | D5: High | E5: Extended ACL 100 explicitly denies traffic from PC0 (192.168.10.10) to Server0 (192.168.20.20), applied outbound on Gi0/1 | F5: Extended ACL 100 denies PC0 -> Server0 traffic, applied outbound on Gi0/1 | G5: high | H5: yes | I5: Accepted | J5: AI diagnosis matched the expected fault and cited the correct evidence.
A6: C05 | B6: Complete | C6: Trunk allowed-VLAN list | D6: Medium | E6: VLAN 10 not included in the trunk's allowed-VLAN list on Switch0 Fa0/2 (only VLAN 1 and 20 permitted) | F6: VLAN 10 missing from the trunk's allowed-VLAN list on Switch0 Fa0/2 | G6: high | H6: yes | I6: Accepted | J6: AI diagnosis matched the expected fault and cited the correct evidence.
A7: C06 | B7: Complete | C7: Duplicate IP | D7: Medium | E7: Duplicate IP address 192.168.10.10 assigned to both PC0 and PC1 | F7: Duplicate IP address 192.168.10.10 assigned to two hosts | G7: high | H7: yes | I7: Accepted | J7: AI diagnosis matched the expected fault and cited the correct evidence.
A8: C07 | B8: Complete | C8: Gateway mismatch | D8: High | E8: PC0 configured with an incorrect default gateway instead of the correct 192.168.10.1 | F8: PC0's default gateway does not match the router interface on its subnet | G8: high | H8: yes | I8: Accepted | J8: AI diagnosis matched the expected fault and cited the correct evidence.
A9: C08 | B9: Complete | C9: Routing protocol mismatch | D9: High | E9: Missing 'network 192.168.20.0' statement under Router1's RIP configuration | F9: RIP is not advertising the remote LAN because auto-summary is misconfigured on Router1 | G9: medium | H9: no | I9: Edited | J9: AI blamed auto-summary, but show ip protocols clearly lists 'Routing for Networks: 10.0.0.0' with no 192.168.20.0 entry at all — the network statement itself is missing, not an auto-summary setting. Reviewer corrected root_cause and evidence citation.
A10: C09 | B10: Complete | C10: Port security violation | D10: High | E10: Incorrect secure MAC address configured on Fa0/1; PC0's real MAC triggered a security violation and err-disabled the port | F10: Fa0/1 was manually shut down by an administrator | G10: medium | H10: no | I10: Rejected | J10: AI assumed a manual shutdown, but the evidence explicitly shows a %PSECURE-2 violation message and Secure-shutdown status with Violation Count: 1 — this is a port-security err-disable, a different mechanism with a different fix (correct the secure MAC + 'shutdown'/'no shutdown' recovery, not just 'no shutdown'). Reviewer rejected and re-ran with a prompt reminder to check for PSECURE messages before assuming a plain admin shutdown.
A11: C10 | B11: Complete | C11: VLAN misconfiguration | D11: High | E11: Fa0/1 assigned to the wrong access VLAN (20 instead of 10) | F11: Fa0/1 assigned to the wrong access VLAN (20 instead of 10) | G11: high | H11: yes | I11: Accepted | J11: AI diagnosis matched the expected fault and cited the correct evidence.
A12: C11 | B12: Complete | C12: Native VLAN mismatch | D12: Medium | E12: Native VLAN mismatch across the Fa0/24 trunk (Switch0=VLAN10, Switch1=VLAN20) | F12: Native VLAN mismatch between Switch0 and Switch1 on the Fa0/24 trunk | G12: high | H12: yes | I12: Accepted | J12: AI diagnosis matched the expected fault and cited the correct evidence.
A13: C12 | B13: Complete | C13: STP root bridge / port role | D13: Medium | E13: SW1 not originally configured with the lowest STP priority to become Root Bridge (fixed by setting VLAN 1 priority to 4096 on SW1) | F13: VLAN 1 is not enabled for spanning-tree on SW1 | G13: medium | H13: no | I13: Edited | J13: AI said VLAN 1 wasn't enabled for STP, but the evidence shows STP running fine — SW1 simply didn't have the lowest priority to win the root election. Reviewer corrected root_cause to the priority/root-election explanation and cited the 'This bridge is the root' line.
A14: C13 | B14: Complete | C14: Wrong DNS server | D14: Medium | E14: PC0 had an incorrect/missing DNS server configuration (should point to Server0 at 192.168.10.11) | F14: Server0's DNS service is not running | G14: medium | H14: no | I14: Edited | J14: AI assumed the DNS server process was down, but the evidence shows Server0's own A record and service were fine — the fault was PC0's client-side DNS server setting pointing to the wrong address. Reviewer corrected root_cause to point at the client configuration, not the server.
A15: C14 | B15: Complete | C15: NAT misconfiguration | D15: High | E15: Missing NAT overload/PAT rule on Router0 ('ip nat inside source list 1 interface gigabitEthernet 0/1 overload' was removed) | F15: NAT overload/PAT rule missing on Router0 | G15: high | H15: yes | I15: Accepted | J15: AI diagnosis matched the expected fault and cited the correct evidence.
A16: C15 | B16: Pending | C16: FTP | D16: Unknown | F16: Not yet diagnosed — evidence pending | H16: pending | I16: Pending Evidence | J16: Case not yet reviewed — awaiting evidence document.
A17: C16 | B17: Pending | C17: VLAN | D17: Unknown | F17: Not yet diagnosed — evidence pending | H17: pending | I17: Pending Evidence | J17: Case not yet reviewed — awaiting evidence document.
A18: C17 | B18: Pending | C18: DHCP | D18: Unknown | F18: Not yet diagnosed — evidence pending | H18: pending | I18: Pending Evidence | J18: Case not yet reviewed — awaiting evidence document.
A19: C18 | B19: Pending | C19: DNS | D19: Unknown | F19: Not yet diagnosed — evidence pending | H19: pending | I19: Pending Evidence | J19: Case not yet reviewed — awaiting evidence document.
A20: C19 | B20: Complete | C20: Missing route | D20: High | E20: Static route to 192.168.30.0/24 via 10.0.0.2 was removed from Router0 ('no ip route 192.168.30.0 255.255.255.0 10.0.0.2') | F20: Static route to 192.168.30.0/24 missing on Router0 | G20: high | H20: yes | I20: Accepted | J20: AI diagnosis matched the expected fault and cited the correct evidence.
A21: C20 | B21: Complete | C21: Missing route | D21: High | E21: Missing static routes on Router0 (to 192.168.20.0/24) and Router1 (return route to 192.168.10.0/24) | F21: Missing static routes on Router0 and Router1 for each other's LANs | G21: high | H21: yes | I21: Accepted | J21: AI diagnosis matched the expected fault and cited the correct evidence.
A22: C21 | B22: Complete | C22: Wrong subnet mask | D22: Medium | E22: PC1 configured with subnet mask 255.255.0.0 instead of 255.255.255.0 | F22: PC1 configured with the wrong subnet mask (255.255.0.0 instead of 255.255.255.0) | G22: high | H22: yes | I22: Accepted | J22: AI diagnosis matched the expected fault and cited the correct evidence.
A23: C22 | B23: Complete | C23: Routing protocol mismatch | D23: High | E23: Incorrect OSPF network statement on Router0 (192.168.100.0/24 instead of the actual LAN 192.168.10.0/24) | F23: Incorrect OSPF network statement on Router0 (192.168.100.0/24 instead of 192.168.10.0/24) | G23: high | H23: yes | I23: Accepted | J23: AI diagnosis matched the expected fault and cited the correct evidence.
A24: C23 | B24: Complete | C24: VLAN misconfiguration | D24: High | E24: Fa0/2 assigned to VLAN 30 instead of VLAN 20 | F24: Fa0/2 assigned to VLAN 30 instead of VLAN 20 | G24: high | H24: yes | I24: Accepted | J24: AI diagnosis matched the expected fault and cited the correct evidence.
A25: C24 | B25: Complete | C25: Interface down | D25: High | E25: GigabitEthernet0/0 administratively shut down on Router0 | F25: GigabitEthernet0/0 administratively shut down on Router0 | G25: high | H25: yes | I25: Accepted | J25: AI diagnosis matched the expected fault and cited the correct evidence.
A26: C25 | B26: Complete | C26: Access/trunk mode mismatch | D26: Medium | E26: PC-facing interface Fa0/1 on SW2 configured as a trunk instead of an access port in VLAN 10 | F26: PC-facing Fa0/1 on SW2 configured as trunk instead of access mode | G26: high | H26: yes | I26: Accepted | J26: AI diagnosis matched the expected fault and cited the correct evidence.
A27: C26 | B27: Complete | C27: EtherChannel member mismatch | D27: Medium | E27: SW2 Fa0/23 configured with switchport mode access instead of trunk, and LACP passive instead of active, excluding it from the bundle | F27: Duplex mismatch on SW2 Fa0/23 causing it to drop from the EtherChannel | G27: medium | H27: no | I27: Edited | J27: AI guessed a duplex mismatch, a generic EtherChannel symptom, but show etherchannel summary plus the interface config clearly show Fa0/23 in access mode with LACP passive while its peers are trunk/active — a configuration mismatch, not a duplex issue. Reviewer corrected root_cause and evidence citation.
A28: C27 | B28: Complete | C28: Application service disabled | D28: Medium | E28: HTTP service disabled on Server1 — an application-layer fault, not a network/IP issue | F28: HTTP service disabled on Server1 | G28: high | H28: yes | I28: Accepted | J28: AI diagnosis matched the expected fault and cited the correct evidence.
A29: C28 | B29: Complete | C29: DHCP relay missing | D29: High | E29: 'ip helper-address 192.168.10.10' removed from both G0/1.20 and G0/1.30 subinterfaces | F29: ip helper-address missing on the VLAN 20 and VLAN 30 router subinterfaces | G29: high | H29: yes | I29: Accepted | J29: AI diagnosis matched the expected fault and cited the correct evidence.
A30: C29 | B30: Pending | C30: NAT | D30: Unknown | F30: Not yet diagnosed — evidence pending | H30: pending | I30: Pending Evidence | J30: Case not yet reviewed — awaiting evidence document.
A31: C30 | B31: Pending | C31: Inter-VLAN Routing | D31: Unknown | F31: Not yet diagnosed — evidence pending | H31: pending | I31: Pending Evidence | J31: Case not yet reviewed — awaiting evidence document.

Sheet Rule_Checker
A1: case_id | B1: expected_fault | C1: checks_triggered | D1: checker_notes | E1: num_checks_triggered
A2: C01 | C2: not run | D2: Evidence pending — rule checker not run for this case yet. | E2: 0
A3: C02 | B3: DHCP service disabled on the router ('no service dhcp') despite the DHCP pool being fully configured | C3: none | D3: No deterministic rule matched — relies on AI/human judgment. | E3: 0
A4: C03 | C4: not run | D4: Evidence pending — rule checker not run for this case yet. | E4: 0
A5: C04 | B5: Extended ACL 100 explicitly denies traffic from PC0 (192.168.10.10) to Server0 (192.168.20.20), applied outbound on Gi0/1 | C5: none | D5: No deterministic rule matched — relies on AI/human judgment. | E5: 0
A6: C05 | B6: VLAN 10 not included in the trunk's allowed-VLAN list on Switch0 Fa0/2 (only VLAN 1 and 20 permitted) | C6: none | D6: No deterministic rule matched — relies on AI/human judgment. | E6: 0
A7: C06 | B7: Duplicate IP address 192.168.10.10 assigned to both PC0 and PC1 | C7: duplicate_ip | D7: Duplicate IP detected: 192.168.10.10 appears more than once. | E7: 1
A8: C07 | B8: PC0 configured with an incorrect default gateway instead of the correct 192.168.10.1 | C8: none | D8: No deterministic rule matched — relies on AI/human judgment. | E8: 0
A9: C08 | B9: Missing 'network 192.168.20.0' statement under Router1's RIP configuration | C9: none | D9: No deterministic rule matched — relies on AI/human judgment. | E9: 0
A10: C09 | B10: Incorrect secure MAC address configured on Fa0/1; PC0's real MAC triggered a security violation and err-disabled the port | C10: none | D10: No deterministic rule matched — relies on AI/human judgment. | E10: 0
A11: C10 | B11: Fa0/1 assigned to the wrong access VLAN (20 instead of 10) | C11: none | D11: No deterministic rule matched — relies on AI/human judgment. | E11: 0
A12: C11 | B12: Native VLAN mismatch across the Fa0/24 trunk (Switch0=VLAN10, Switch1=VLAN20) | C12: none | D12: No deterministic rule matched — relies on AI/human judgment. | E12: 0
A13: C12 | B13: SW1 not originally configured with the lowest STP priority to become Root Bridge (fixed by setting VLAN 1 priority to 4096 on SW1) | C13: none | D13: No deterministic rule matched — relies on AI/human judgment. | E13: 0
A14: C13 | B14: PC0 had an incorrect/missing DNS server configuration (should point to Server0 at 192.168.10.11) | C14: none | D14: No deterministic rule matched — relies on AI/human judgment. | E14: 0
A15: C14 | B15: Missing NAT overload/PAT rule on Router0 ('ip nat inside source list 1 interface gigabitEthernet 0/1 overload' was removed) | C15: none | D15: No deterministic rule matched — relies on AI/human judgment. | E15: 0
A16: C15 | C16: not run | D16: Evidence pending — rule checker not run for this case yet. | E16: 0
A17: C16 | C17: not run | D17: Evidence pending — rule checker not run for this case yet. | E17: 0
A18: C17 | C18: not run | D18: Evidence pending — rule checker not run for this case yet. | E18: 0
A19: C18 | C19: not run | D19: Evidence pending — rule checker not run for this case yet. | E19: 0
A20: C19 | B20: Static route to 192.168.30.0/24 via 10.0.0.2 was removed from Router0 ('no ip route 192.168.30.0 255.255.255.0 10.0.0.2') | C20: mask_mismatch | D20: Multiple CIDR prefix lengths found on hosts expected to share a subnet: ['24', '30']. | E20: 1
A21: C20 | B21: Missing static routes on Router0 (to 192.168.20.0/24) and Router1 (return route to 192.168.10.0/24) | C21: mask_mismatch | D21: Multiple CIDR prefix lengths found on hosts expected to share a subnet: ['24', '30']. | E21: 1
A22: C21 | B22: PC1 configured with subnet mask 255.255.0.0 instead of 255.255.255.0 | C22: none | D22: No deterministic rule matched — relies on AI/human judgment. | E22: 0
A23: C22 | B23: Incorrect OSPF network statement on Router0 (192.168.100.0/24 instead of the actual LAN 192.168.10.0/24) | C23: none | D23: No deterministic rule matched — relies on AI/human judgment. | E23: 0
A24: C23 | B24: Fa0/2 assigned to VLAN 30 instead of VLAN 20 | C24: none | D24: No deterministic rule matched — relies on AI/human judgment. | E24: 0
A25: C24 | B25: GigabitEthernet0/0 administratively shut down on Router0 | C25: interface_down | D25: Interface is administratively down (shutdown) — a human should verify this was intentional. | E25: 1
A26: C25 | B26: PC-facing interface Fa0/1 on SW2 configured as a trunk instead of an access port in VLAN 10 | C26: none | D26: No deterministic rule matched — relies on AI/human judgment. | E26: 0
A27: C26 | B27: SW2 Fa0/23 configured with switchport mode access instead of trunk, and LACP passive instead of active, excluding it from the bundle | C27: none | D27: No deterministic rule matched — relies on AI/human judgment. | E27: 0
A28: C27 | B28: HTTP service disabled on Server1 — an application-layer fault, not a network/IP issue | C28: none | D28: No deterministic rule matched — relies on AI/human judgment. | E28: 0
A29: C28 | B29: 'ip helper-address 192.168.10.10' removed from both G0/1.20 and G0/1.30 subinterfaces | C29: none | D29: No deterministic rule matched — relies on AI/human judgment. | E29: 0
A30: C29 | C30: not run | D30: Evidence pending — rule checker not run for this case yet. | E30: 0
A31: C30 | C31: not run | D31: Evidence pending — rule checker not run for this case yet. | E31: 0

Sheet Case_Tracker
B2: Evidence Still Needed
B3: These .pkt topologies have been received but still need an evidence document before they can be diagnosed.
B5: case_id | C5: pkt_file | D5: concept_tag
B6: C01 | C6: Cisco__1__DNS_Problem_.pkt | D6: DNS
B7: C03 | C7: Cisco__3__Gateway_Problem_.pkt | D7: Gateway
B8: C15 | C8: Cisco__15__FTP_Server_Error_.pkt | D8: FTP
B9: C16 | C9: Cisco__16__Baseline_VLAN20_.pkt | D9: VLAN
B10: C17 | C10: Cisco__17__DHCP_Problem_.pkt | D10: DHCP
B11: C18 | C11: Cisco__18__DNS_Troubleshooting_.pkt | D11: DNS
B12: C29 | C12: Cisco__29__NAT_Working_Baseline_.pkt | D12: NAT
B13: C30 | C13: Cisco__30__Inter-VLAN_Routing_.pkt | D13: Inter-VLAN Routing
